Workbook

Sheet Results
A1: Instance | B1: DP | D1: TS | F1: HLA | H1: GRB | J1: PWL-BC | L1: Gaps
B2: Obj | C2: Time (s) | D2: Obj | E2: Time (s) | F2: Obj | G2: Time (s) | H2: Obj | I2: Time (s) | J2: Obj | K2: Time (s) | L2: Obj GRB-DP | M2: Obj GRB-DP (%) | N2: Time GRB-DP (s) | O2: Time GRB-DP (%) | P2: Obj PWL-DP | Q2: Obj PWL-DP (%) | R2: Time PWL-DP (s) | S2: Time PWL-DP (%) | T2: Obj DP-TS | U2: Obj DP-TS (%) | V2: Obj DP-HLA | W2: Obj DP-HLA (%)
A3: RP_ICR_N-100_I-0_R-0.95 | B3: 2804 | C3: 0.026 | D3: 2783 | E3: 0.001 | F3: 2804 | G3: 0.02 | H3: 2804 | I3: 3.27178 | J3: 2804 | K3: 1.895 | L3: =H3-B3 -> 0 | M3: =L3*100/B3 -> 0 | N3: =I3-C3 -> 3.24578 | O3: =N3*100/C3 -> 12483.769 | P3: =J3-B3 -> 0 | Q3: =P3*100/B3 -> 0 | R3: =K3-C3 -> 1.869 | S3: =R3*100/C3 -> 7188.4615 | T3: =B3-D3 -> 21 | U3: =T3*100/B3 -> 0.7489301 | V3: =B3-F3 -> 0 | W3: =V3*100/B3 -> 0
A4: RP_ICR_N-100_I-0_R-0.99 | B4: 2672 | C4: 0.061 | D4: 2641 | E4: 0.001 | F4: 2672 | G4: 0.023 | H4: 2672 | I4: 0.553016 | J4: 2672 | K4: 1.699 | L4: =H4-B4 -> 0 | M4: =L4*100/B4 -> 0 | N4: =I4-C4 -> 0.492016 | O4: =N4*100/C4 -> 806.58361 | P4: =J4-B4 -> 0 | Q4: =P4*100/B4 -> 0 | R4: =K4-C4 -> 1.638 | S4: =R4*100/C4 -> 2685.2459 | T4: =B4-D4 -> 31 | U4: =T4*100/B4 -> 1.1601796 | V4: =B4-F4 -> 0 | W4: =V4*100/B4 -> 0
A5: RP_ICR_N-100_I-10_R-0.95 | B5: 2720 | C5: 0.025 | D5: 2687 | E5: 0.001 | F5: 2720 | G5: 0.02 | H5: 2720 | I5: 2.26607 | J5: 2720 | K5: 2.292 | L5: =H5-B5 -> 0 | M5: =L5*100/B5 -> 0 | N5: =I5-C5 -> 2.24107 | O5: =N5*100/C5 -> 8964.28 | P5: =J5-B5 -> 0 | Q5: =P5*100/B5 -> 0 | R5: =K5-C5 -> 2.267 | S5: =R5*100/C5 -> 9068 | T5: =B5-D5 -> 33 | U5: =T5*100/B5 -> 1.2132353 | V5: =B5-F5 -> 0 | W5: =V5*100/B5 -> 0
A6: RP_ICR_N-100_I-10_R-0.99 | B6: 2587 | C6: 0.041 | D6: 2534 | E6: 0.001 | F6: 2587 | G6: 0.022 | H6: 2587 | I6: 0.951694 | J6: 2587 | K6: 1.666 | L6: =H6-B6 -> 0 | M6: =L6*100/B6 -> 0 | N6: =I6-C6 -> 0.910694 | O6: =N6*100/C6 -> 2221.2049 | P6: =J6-B6 -> 0 | Q6: =P6*100/B6 -> 0 | R6: =K6-C6 -> 1.625 | S6: =R6*100/C6 -> 3963.4146 | T6: =B6-D6 -> 53 | U6: =T6*100/B6 -> 2.0487051 | V6: =B6-F6 -> 0 | W6: =V6*100/B6 -> 0
A7: RP_ICR_N-100_I-11_R-0.95 | B7: 2651 | C7: 0.027 | D7: 2634 | E7: 0.001 | F7: 2651 | G7: 0.021 | H7: 2651 | I7: 2.2842 | J7: 2651 | K7: 1.591 | L7: =H7-B7 -> 0 | M7: =L7*100/B7 -> 0 | N7: =I7-C7 -> 2.2572 | O7: =N7*100/C7 -> 8360 | P7: =J7-B7 -> 0 | Q7: =P7*100/B7 -> 0 | R7: =K7-C7 -> 1.564 | S7: =R7*100/C7 -> 5792.5926 | T7: =B7-D7 -> 17 | U7: =T7*100/B7 -> 0.64126745 | V7: =B7-F7 -> 0 | W7: =V7*100/B7 -> 0
A8: RP_ICR_N-100_I-11_R-0.99 | B8: 2520 | C8: 0.07 | D8: 2494 | E8: 0.001 | F8: 2520 | G8: 0.024 | H8: 2520 | I8: 0.744371 | J8: 2520 | K8: 1.875 | L8: =H8-B8 -> 0 | M8: =L8*100/B8 -> 0 | N8: =I8-C8 -> 0.674371 | O8: =N8*100/C8 -> 963.38714 | P8: =J8-B8 -> 0 | Q8: =P8*100/B8 -> 0 | R8: =K8-C8 -> 1.805 | S8: =R8*100/C8 -> 2578.5714 | T8: =B8-D8 -> 26 | U8: =T8*100/B8 -> 1.031746 | V8: =B8-F8 -> 0 | W8: =V8*100/B8 -> 0
A9: RP_ICR_N-100_I-12_R-0.95 | B9: 2509 | C9: 0.024 | D9: 2458 | E9: 0.001 | F9: 2509 | G9: 0.019 | H9: 2509 | I9: 0.328487 | J9: 2509 | K9: 1.275 | L9: =H9-B9 -> 0 | M9: =L9*100/B9 -> 0 | N9: =I9-C9 -> 0.304487 | O9: =N9*100/C9 -> 1268.6958 | P9: =J9-B9 -> 0 | Q9: =P9*100/B9 -> 0 | R9: =K9-C9 -> 1.251 | S9: =R9*100/C9 -> 5212.5 | T9: =B9-D9 -> 51 | U9: =T9*100/B9 -> 2.0326823 | V9: =B9-F9 -> 0 | W9: =V9*100/B9 -> 0
A10: RP_ICR_N-100_I-12_R-0.99 | B10: 2373 | C10: 0.042 | D10: 2313 | E10: 0.001 | F10: 2373 | G10: 0.021 | H10: 2373 | I10: 0.664171 | J10: 2373 | K10: 1.344 | L10: =H10-B10 -> 0 | M10: =L10*100/B10 -> 0 | N10: =I10-C10 -> 0.622171 | O10: =N10*100/C10 -> 1481.3595 | P10: =J10-B10 -> 0 | Q10: =P10*100/B10 -> 0 | R10: =K10-C10 -> 1.302 | S10: =R10*100/C10 -> 3100 | T10: =B10-D10 -> 60 | U10: =T10*100/B10 -> 2.528445 | V10: =B10-F10 -> 0 | W10: =V10*100/B10 -> 0
A11: RP_ICR_N-100_I-13_R-0.95 | B11: 2451 | C11: 0.021 | D11: 2412 | E11: 0.001 | F11: 2451 | G11: 0.018 | H11: 2451 | I11: 0.504831 | J11: 2451 | K11: 1.626 | L11: =H11-B11 -> 0 | M11: =L11*100/B11 -> 0 | N11: =I11-C11 -> 0.483831 | O11: =N11*100/C11 -> 2303.9571 | P11: =J11-B11 -> 0 | Q11: =P11*100/B11 -> 0 | R11: =K11-C11 -> 1.605 | S11: =R11*100/C11 -> 7642.8571 | T11: =B11-D11 -> 39 | U11: =T11*100/B11 -> 1.5911873 | V11: =B11-F11 -> 0 | W11: =V11*100/B11 -> 0
A12: RP_ICR_N-100_I-13_R-0.99 | B12: 2314 | C12: 0.031 | D12: 2314 | E12: 0.001 | F12: 2314 | G12: 0.02 | H12: 2314 | I12: 0.686314 | J12: 2314 | K12: 1.581 | L12: =H12-B12 -> 0 | M12: =L12*100/B12 -> 0 | N12: =I12-C12 -> 0.655314 | O12: =N12*100/C12 -> 2113.9161 | P12: =J12-B12 -> 0 | Q12: =P12*100/B12 -> 0 | R12: =K12-C12 -> 1.55 | S12: =R12*100/C12 -> 5000 | T12: =B12-D12 -> 0 | U12: =T12*100/B12 -> 0 | V12: =B12-F12 -> 0 | W12: =V12*100/B12 -> 0
A13: RP_ICR_N-100_I-14_R-0.95 | B13: 2635 | C13: 0.027 | D13: 2589 | E13: 0.001 | F13: 2635 | G13: 0.018 | H13: 2635 | I13: 0.519342 | J13: 2635 | K13: 1.609 | L13: =H13-B13 -> 0 | M13: =L13*100/B13 -> 0 | N13: =I13-C13 -> 0.492342 | O13: =N13*100/C13 -> 1823.4889 | P13: =J13-B13 -> 0 | Q13: =P13*100/B13 -> 0 | R13: =K13-C13 -> 1.582 | S13: =R13*100/C13 -> 5859.2593 | T13: =B13-D13 -> 46 | U13: =T13*100/B13 -> 1.7457305 | V13: =B13-F13 -> 0 | W13: =V13*100/B13 -> 0
A14: RP_ICR_N-100_I-14_R-0.99 | B14: 2496 | C14: 0.056 | D14: 2440 | E14: 0.001 | F14: 2496 | G14: 0.022 | H14: 2496 | I14: 0.534985 | J14: 2496 | K14: 1.308 | L14: =H14-B14 -> 0 | M14: =L14*100/B14 -> 0 | N14: =I14-C14 -> 0.478985 | O14: =N14*100/C14 -> 855.33036 | P14: =J14-B14 -> 0 | Q14: =P14*100/B14 -> 0 | R14: =K14-C14 -> 1.252 | S14: =R14*100/C14 -> 2235.7143 | T14: =B14-D14 -> 56 | U14: =T14*100/B14 -> 2.2435897 | V14: =B14-F14 -> 0 | W14: =V14*100/B14 -> 0
... A3602: RP_SS_N-900_I-9_R-0.99 | B3602: 21726 | C3602: 46.546 | D3602: 21628 | E3602: 0.18 | F3602: 21726 | G3602: 6.275 | H3602: 21726 | I3602: 2.04766 | J3602: 21724 | K3602: 2.469 | L3602: =H3602-B3602 -> 0 | M3602: =L3602*100/B3602 -> 0 | N3602: =I3602-C3602 -> -44.49834 | O3602: =N3602*100/C3602 -> -95.600782 | P3602: =J3602-B3602 -> -2 | Q3602: =P3602*100/B3602 -> -0.0092055602 | R3602: =K3602-C3602 -> -44.077 | S3602: =R3602*100/C3602 -> -94.69557 | T3602: =B3602-D3602 -> 98 | U3602: =T3602*100/B3602 -> 0.45107245 | V3602: =B3602-F3602 -> 0 | W3602: =V3602*100/B3602 -> 0
A3603: AVG | B3603: =AVERAGE(B3:B3602) -> 13118.476 | C3603: =AVERAGE(C3:C3602) -> 8.7434475 | D3603: =AVERAGE(D3:D3602) -> 13017.45 | E3603: =AVERAGE(E3:E3602) -> 0.031635556 | F3603: =AVERAGE(F3:F3602) -> 13112.794 | G3603: =AVERAGE(G3:G3602) -> 1.1408925 | H3603: =AVERAGE(H3:H3602) -> 13057.99 | I3603: =AVERAGE(I3:I3602) -> 70.513164 | J3603: 12576.329 | K3603: 244.44347 | L3603: =AVERAGE(L3:L3602) -> -60.485278 | M3603: =AVERAGE(M3:M3602) -> -0.25001984 | N3603: =AVERAGE(N3:N3602) -> 61.769716 | O3603: =AVERAGE(O3:O3602) -> 3935.3574 | P3603: =AVERAGE(P3:P3602) -> -542.17139 | Q3603: =AVERAGE(Q3:Q3602) -> -2.5286937 | R3603: =AVERAGE(R3:R3602) -> 235.70065 | S3603: =AVERAGE(S3:S3602) -> 36113.105 | T3603: =B3603-D3603 -> 101.02556 | U3603: =AVERAGE(U3:U3602) -> 0.92300413 | V3603: =AVERAGE(V3:V3602) -> 5.6813889 | W3603: =AVERAGE(W3:W3602) -> 0.0439101

Sheet Stats
A1: FILENAME | B1: n | C1: q | D1: CLASS | E1: PEARSON CORR. COEFF. p, a | F1: PEARSON CORR. COEFF. b, a | G1: AVG RATIO b_i/a_i | H1: AVG RATIO sigma_i/a_i | I1: PERCENTAGE MEANINGFUL ITEMS
A2: RP_ICR_N-100_I-0_R-0.95 | B2: 100 | C2: 3192 | D2: ICR | E2: 0.99783549 | F2: -0.87286839 | G2: 1.3045046 | H2: 0.16406005 | I2: 91
A3: RP_ICR_N-100_I-0_R-0.99 | B3: 100 | C3: 3192 | D3: ICR | E3: 0.99783549 | F3: -0.87286839 | G3: 1.3045046 | H3: 0.16406005 | I3: 91
A4: RP_ICR_N-100_I-10_R-0.95 | B4: 100 | C4: 3126 | D4: ICR | E4: 0.99883008 | F4: -0.90870625 | G4: 1.3716847 | H4: 0.16992937 | I4: 85
A5: RP_ICR_N-100_I-10_R-0.99 | B5: 100 | C5: 3126 | D5: ICR | E5: 0.99883008 | F5: -0.90870625 | G5: 1.3716847 | H5: 0.16992937 | I5: 85
A6: RP_ICR_N-100_I-11_R-0.95 | B6: 100 | C6: 3032 | D6: ICR | E6: 0.99779135 | F6: -0.89357438 | G6: 1.5271365 | H6: 0.18604888 | I6: 84
A7: RP_ICR_N-100_I-11_R-0.99 | B7: 100 | C7: 3032 | D7: ICR | E7: 0.99779135 | F7: -0.89357438 | G7: 1.5271365 | H7: 0.18604888 | I7: 84
A8: RP_ICR_N-100_I-12_R-0.95 | B8: 100 | C8: 2915 | D8: ICR | E8: 0.99833077 | F8: -0.90143751 | G8: 1.4448547 | H8: 0.17840933 | I8: 84
A9: RP_ICR_N-100_I-12_R-0.99 | B9: 100 | C9: 2915 | D9: ICR | E9: 0.99833077 | F9: -0.90143751 | G9: 1.4448547 | H9: 0.17840933 | I9: 84
A10: RP_ICR_N-100_I-13_R-0.95 | B10: 100 | C10: 2854 | D10: ICR | E10: 0.99875885 | F10: -0.90291858 | G10: 1.6133045 | H10: 0.19613402 | I10: 84
A11: RP_ICR_N-100_I-13_R-0.99 | B11: 100 | C11: 2854 | D11: ICR | E11: 0.99875885 | F11: -0.90291858 | G11: 1.6133045 | H11: 0.19613402 | I11: 84
A12: RP_ICR_N-100_I-14_R-0.95 | B12: 100 | C12: 3037 | D12: ICR | E12: 0.99890549 | F12: -0.89252742 | G12: 1.5634613 | H12: 0.19018873 | I12: 82
A13: RP_ICR_N-100_I-14_R-0.99 | B13: 100 | C13: 3037 | D13: ICR | E13: 0.99890549 | F13: -0.89252742 | G13: 1.5634613 | H13: 0.19018873 | I13: 82
... A3601: RP_SS_N-900_I-9_R-0.99 | B3601: 900 | C3601: 22726 | D3601: SS | E3601: 1 | F3601: 0.96777627 | G3601: 0.50502222 | H3601: 0.1 | I3601: 100

Sheet ParameterTuning-Summary
A1: theta x version | B1: def | C1: maskHLA | D1: maskTS | G1: theta x version | H1: def | I1: maskHLA | J1: maskTS
A2: 0 | B2: ='theta=0'!B191 -> 315.90243 | C2: ='theta=0'!C191 -> 334.37425 | D2: ='theta=0'!D191 -> 316.15073 | G2: 0 | H2: ='theta=0'!B188 -> 11.6085 | I2: ='theta=0'!C188 -> 15.006 | J2: ='theta=0'!D188 -> 12.2325
A3: 1 | B3: ='theta=1'!B191 -> 232.17114 | C3: ='theta=1'!C191 -> 234.24214 | D3: ='theta=1'!D191 -> 232.2997 | G3: 1 | H3: ='theta=1'!B188 -> 4.486 | I3: ='theta=1'!C188 -> 4.9865 | J3: ='theta=1'!D188 -> 4.55
A4: 3 | B4: ='theta=3'!B191 -> 124.41702 | C4: ='theta=3'!C191 -> 105.28082 | D4: ='theta=3'!D191 -> 124.49681 | G4: 3 | H4: ='theta=3'!B188 -> 1.953 | I4: ='theta=3'!C188 -> 2.047 | J4: ='theta=3'!D188 -> 2.1755
A5: 6 | B5: ='theta=6'!B191 -> 44.963439 | C5: ='theta=6'!C191 -> 46.139428 | D5: ='theta=6'!D191 -> 44.300178 | G5: 6 | H5: ='theta=6'!B188 -> 1.357 | I5: ='theta=6'!C188 -> 1.1115 | J5: ='theta=6'!D188 -> 1.7545
A6: 10 | B6: ='theta=10'!B191 -> 22.041561 | C6: ='theta=10'!C191 -> 21.749778 | D6: ='theta=10'!D191 -> 21.92845 | G6: 10 | H6: ='theta=10'!B188 -> 1.333 | I6: ='theta=10'!C188 -> 0.9265 | J6: ='theta=10'!D188 -> 1.5445
A7: 15 | B7: ='theta=15'!B191 -> 13.512361 | C7: ='theta=15'!C191 -> 12.850394 | D7: ='theta=15'!D191 -> 13.493294 | G7: 15 | H7: ='theta=15'!B188 -> 1.302 | I7: ='theta=15'!C188 -> 0.879 | J7: ='theta=15'!D188 -> 1.609
A8: 20 | B8: ='theta=20'!B191 -> 10.5309 | C8: ='theta=20'!C191 -> 9.7795444 | D8: ='theta=20'!D191 -> 10.651189 | G8: 20 | H8: ='theta=20'!B188 -> 1.3725 | I8: ='theta=20'!C188 -> 0.9205 | J8: ='theta=20'!D188 -> 1.745
A9: 25 | B9: ='theta=25'!B191 -> 9.6008444 | C9: ='theta=25'!C191 -> 8.7319833 | D9: ='theta=25'!D191 -> 9.80945 | G9: 25 | H9: ='theta=25'!B188 -> 1.4945 | I9: ='theta=25'!C188 -> 0.9345 | J9: ='theta=25'!D188 -> 1.8225
A10: 30 | B10: ='theta=30'!B191 -> 9.2121444 | C10: ='theta=30'!C191 -> 8.0945611 | D10: ='theta=30'!D191 -> 9.3717278 | G10: 30 | H10: ='theta=30'!B188 -> 1.538 | I10: ='theta=30'!C188 -> 0.9655 | J10: ='theta=30'!D188 -> 1.866
A11: 35 | B11: ='theta=35'!B191 -> 9.20195 | C11: ='theta=35'!C191 -> 8.23875 | D11: ='theta=35'!D191 -> 9.5671222 | G11: 35 | H11: ='theta=35'!B188 -> 1.579 | I11: ='theta=35'!C188 -> 0.992 | J11: ='theta=35'!D188 -> 1.825
A12: inf | B12: ='theta=inf'!B191 -> 325.97931 | C12: ='theta=inf'!C191 -> 210.11692 | D12: ='theta=inf'!D191 -> 352.72911 | G12: inf | H12: ='theta=inf'!B188 -> 78.1335 | I12: ='theta=inf'!C188 -> 48.392 | J12: ='theta=inf'!D188 -> 79.3555
B13: ='theta=35'!B193 | C13: ='theta=35'!C193 | D13: ='theta=35'!D193
A15: theta x version | B15: def | C15: maskHLA | D15: maskTS | G15: theta x version | H15: def | I15: maskHLA | J15: maskTS
A16: 0 | B16: ='theta=0'!M200 -> 80772964 | C16: ='theta=0'!N200 -> 90587271 | D16: ='theta=0'!O200 -> 80772964 | G16: 0 | H16: =B16/min(Avg._Nondom._Labels[[def]:[maskTS]]) -> 15.746462 | I16: =C16/min(Avg._Nondom._Labels[[def]:[maskTS]]) -> 17.659734 | J16: =D16/min(Avg._Nondom._Labels[[def]:[maskTS]]) -> 15.746462
A17: 1 | B17: ='theta=1'!M200 -> 27329839 | C17: ='theta=1'!N200 -> 29973586 | D17: ='theta=1'!O200 -> 27329839 | G17: 1 | H17: =B17/min(Avg._Nondom._Labels[[def]:[maskTS]]) -> 5.3278754 | I17: =C17/min(Avg._Nondom._Labels[[def]:[maskTS]]) -> 5.8432664 | J17: =D17/min(Avg._Nondom._Labels[[def]:[maskTS]]) -> 5.3278754
A18: 3 | B18: ='theta=3'!M200 -> 20966920 | C18: ='theta=3'!N200 -> 22491897 | D18: ='theta=3'!O200 -> 20966920 | G18: 3 | H18: =B18/min(Avg._Nondom._Labels[[def]:[maskTS]]) -> 4.0874421 | I18: =C18/min(Avg._Nondom._Labels[[def]:[maskTS]]) -> 4.3847321 | J18: =D18/min(Avg._Nondom._Labels[[def]:[maskTS]]) -> 4.0874421
A19: 6 | B19: ='theta=6'!M200 -> 21616618 | C19: ='theta=6'!N200 -> 23115713 | D19: ='theta=6'!O200 -> 21616618 | G19: 6 | H19: =B19/min(Avg._Nondom._Labels[[def]:[maskTS]]) -> 4.2140989 | I19: =C19/min(Avg._Nondom._Labels[[def]:[maskTS]]) -> 4.5063433 | J19: =D19/min(Avg._Nondom._Labels[[def]:[maskTS]]) -> 4.2140989
A20: 10 | B20: ='theta=10'!M200 -> 13533454 | C20: ='theta=10'!N200 -> 14426225 | D20: ='theta=10'!O200 -> 13533454 | G20: 10 | H20: =B20/min(Avg._Nondom._Labels[[def]:[maskTS]]) -> 2.6383089 | I20: =C20/min(Avg._Nondom._Labels[[def]:[maskTS]]) -> 2.812352 | J20: =D20/min(Avg._Nondom._Labels[[def]:[maskTS]]) -> 2.6383089
A21: 15 | B21: ='theta=15'!M200 -> 9730275.7 | C21: ='theta=15'!N200 -> 10327781 | D21: ='theta=15'!O200 -> 9730275.7 | G21: 15 | H21: =B21/min(Avg._Nondom._Labels[[def]:[maskTS]]) -> 1.8968899 | I21: =C21/min(Avg._Nondom._Labels[[def]:[maskTS]]) -> 2.0133719 | J21: =D21/min(Avg._Nondom._Labels[[def]:[maskTS]]) -> 1.8968899
A22: 20 | B22: ='theta=20'!M200 -> 7913080.1 | C22: ='theta=20'!N200 -> 8388336.7 | D22: ='theta=20'!O200 -> 7913080.1 | G22: 20 | H22: =B22/min(Avg._Nondom._Labels[[def]:[maskTS]]) -> 1.5426327 | I22: =C22/min(Avg._Nondom._Labels[[def]:[maskTS]]) -> 1.6352827 | J22: =D22/min(Avg._Nondom._Labels[[def]:[maskTS]]) -> 1.5426327
A23: 25 | B23: ='theta=25'!M200 -> 7129186.6 | C23: ='theta=25'!N200 -> 7559166.5 | D23: ='theta=25'!O200 -> 7129186.6 | G23: 25 | H23: =B23/min(Avg._Nondom._Labels[[def]:[maskTS]]) -> 1.3898149 | I23: =C23/min(Avg._Nondom._Labels[[def]:[maskTS]]) -> 1.4736383 | J23: =D23/min(Avg._Nondom._Labels[[def]:[maskTS]]) -> 1.3898149
A24: 30 | B24: ='theta=30'!M200 -> 6498350.1 | C24: ='theta=30'!N200 -> 6910647.5 | D24: ='theta=30'!O200 -> 6498350.1 | G24: 30 | H24: =B24/min(Avg._Nondom._Labels[[def]:[maskTS]]) -> 1.2668351 | I24: =C24/min(Avg._Nondom._Labels[[def]:[maskTS]]) -> 1.3472113 | J24: =D24/min(Avg._Nondom._Labels[[def]:[maskTS]]) -> 1.2668351
A25: 35 | B25: ='theta=35'!M200 -> 5942521.1 | C25: ='theta=35'!N200 -> 6358501.2 | D25: ='theta=35'!O200 -> 5942521.1 | G25: 35 | H25: =B25/min(Avg._Nondom._Labels[[def]:[maskTS]]) -> 1.1584778 | I25: =C25/min(Avg._Nondom._Labels[[def]:[maskTS]]) -> 1.2395719 | J25: =D25/min(Avg._Nondom._Labels[[def]:[maskTS]]) -> 1.1584778
A26: inf | B26: ='theta=inf'!M200 -> 5129594.3 | C26: ='theta=inf'!N200 -> 5427682.4 | D26: ='theta=inf'!O200 -> 5129594.3 | G26: inf | H26: =B26/min(Avg._Nondom._Labels[[def]:[maskTS]]) -> 1 | I26: =C26/min(Avg._Nondom._Labels[[def]:[maskTS]]) -> 1.0581114 | J26: =D26/min(Avg._Nondom._Labels[[def]:[maskTS]]) -> 1

Sheet theta=0
A1: Filename | B1: 1-def | O1: 3-maskHLA | AB1: 4-maskTS
B2: My_Obj_Val | C2: My_Time_s | D2: My_TS_Val | E2: my_TSTime | F2: My_HLA_Val | G2: my_fracKPTime | H2: My_HLATime | I2: My_exactTime | J2: my_labelNum | K2: my_nonlabelNum | L2: my_CBfathomedlabelNum | M2: my_dominatedlabelNum | N2: non_dominated | O2: My_Obj_Val | P2: My_Time_s | Q2: My_TS_Val | R2: my_TSTime | S2: My_HLA_Val | T2: my_fracKPTime | U2: My_HLATime | V2: My_exactTime | W2: my_labelNum | X2: my_nonlabelNum | Y2: my_CBfathomedlabelNum | Z2: my_dominatedlabelNum | AA2: non-dominated | AB2: My_Obj_Val | AC2: My_Time_s | AD2: My_TS_Val | AE2: my_TSTime | AF2: My_HLA_Val | AG2: my_fracKPTime | AH2: My_HLATime | AI2: My_exactTime | AJ2: my_labelNum | AK2: my_nonlabelNum | AL2: my_CBfathomedlabelNum | AM2: my_dominatedlabelNum | AN2: non-dominated
A3: RP_ICR_N-100_I-0_R-0.95 | B3: 2804 | C3: 0.085 | D3: 2783 | E3: 0.001 | F3: 2804 | G3: 0.002 | H3: 0.02 | I3: 0.055 | J3: 327017 | K3: 2 | L3: 36306 | M3: 133407 | N3: =J3-(L3+M3) -> 157304 | O3: 2804 | P3: 0.118 | Q3: 2783 | R3: 0.001 | S3: 0 | T3: 0.002 | U3: 0 | V3: 0.108 | W3: 554002 | X3: 2 | Y3: 48049 | Z3: 242916 | AA3: =W3-(Y3+Z3) -> 263037 | AB3: 2804 | AC3: 0.09 | AD3: 0 | AE3: 0 | AF3: 2804 | AG3: 0.002 | AH3: 0.027 | AI3: 0.055 | AJ3: 327017 | AK3: 2 | AL3: 36306 | AM3: 133407 | AN3: =AJ3-(AL3+AM3) -> 157304
A4: RP_ICR_N-100_I-0_R-0.99 | B4: 2672 | C4: 0.565 | D4: 2641 | E4: 0.001 | F4: 2672 | G4: 0.002 | H4: 0.036 | I4: 0.519 | J4: 1785091 | K4: 2 | L4: 212694 | M4: 724178 | N4: =J4-(L4+M4) -> 848219 | O4: 2672 | P4: 0.712 | Q4: 2641 | R4: 0.001 | S4: 0 | T4: 0.002 | U4: 0 | V4: 0.703 | W4: 2219857 | X4: 2 | Y4: 215082 | Z4: 951247 | AA4: =W4-(Y4+Z4) -> 1053528 | AB4: 2672 | AC4: 0.563 | AD4: 0 | AE4: 0 | AF4: 2672 | AG4: 0.002 | AH4: 0.036 | AI4: 0.519 | AJ4: 1785091 | AK4: 2 | AL4: 212694 | AM4: 724178 | AN4: =AJ4-(AL4+AM4) -> 848219
A5: RP_ICR_N-100_I-1_R-0.95 | B5: 2767 | C5: 0.103 | D5: 2759 | E5: 0.001 | F5: 2767 | G5: 0.002 | H5: 0.018 | I5: 0.076 | J5: 402325 | K5: 2 | L5: 43522 | M5: 168983 | N5: =J5-(L5+M5) -> 189820 | O5: 2767 | P5: 0.122 | Q5: 2759 | R5: 0.001 | S5: 0 | T5: 0.002 | U5: 0 | V5: 0.113 | W5: 545186 | X5: 2 | Y5: 49218 | Z5: 239705 | AA5: =W5-(Y5+Z5) -> 256263 | AB5: 2767 | AC5: 0.106 | AD5: 0 | AE5: 0 | AF5: 2767 | AG5: 0.002 | AH5: 0.023 | AI5: 0.076 | AJ5: 402325 | AK5: 2 | AL5: 43522 | AM5: 168983 | AN5: =AJ5-(AL5+AM5) -> 189820
A6: RP_ICR_N-100_I-1_R-0.99 | B6: 2633 | C6: 0.909 | D6: 2598 | E6: 0.001 | F6: 2633 | G6: 0.002 | H6: 0.039 | I6: 0.861 | J6: 2433476 | K6: 2 | L6: 249658 | M6: 1025564 | N6: =J6-(L6+M6) -> 1158254 | O6: 2633 | P6: 1.244 | Q6: 2598 | R6: 0.001 | S6: 0 | T6: 0.002 | U6: 0 | V6: 1.236 | W6: 3032405 | X6: 2 | Y6: 258090 | Z6: 1336451 | AA6: =W6-(Y6+Z6) -> 1437864 | AB6: 2633 | AC6: 0.909 | AD6: 0 | AE6: 0 | AF6: 2633 | AG6: 0.002 | AH6: 0.039 | AI6: 0.862 | AJ6: 2433476 | AK6: 2 | AL6: 249658 | AM6: 1025564 | AN6: =AJ6-(AL6+AM6) -> 1158254
A7: RP_ICR_N-100_I-2_R-0.95 | B7: 2778 | C7: 0.102 | D7: 2722 | E7: 0.001 | F7: 2778 | G7: 0.002 | H7: 0.025 | I7: 0.069 | J7: 371323 | K7: 3 | L7: 48870 | M7: 149245 | N7: =J7-(L7+M7) -> 173208 | O7: 2778 | P7: 0.284 | Q7: 2722 | R7: 0.001 | S7: 0 | T7: 0.002 | U7: 0 | V7: 0.275 | W7: 978119 | X7: 3 | Y7: 79472 | Z7: 444542 | AA7: =W7-(Y7+Z7) -> 454105 | AB7: 2778 | AC7: 0.105 | AD7: 0 | AE7: 0 | AF7: 2778 | AG7: 0.002 | AH7: 0.028 | AI7: 0.069 | AJ7: 371323 | AK7: 3 | AL7: 48870 | AM7: 149245 | AN7: =AJ7-(AL7+AM7) -> 173208
A8: RP_ICR_N-100_I-2_R-0.99 | B8: 2638 | C8: 1.14 | D8: 2631 | E8: 0.001 | F8: 2638 | G8: 0.002 | H8: 0.044 | I8: 1.085 | J8: 2996151 | K8: 2 | L8: 296297 | M8: 1263555 | N8: =J8-(L8+M8) -> 1436299 | O8: 2638 | P8: 1.16 | Q8: 2631 | R8: 0.001 | S8: 0 | T8: 0.002 | U8: 0 | V8: 1.15 | W8: 3142305 | X8: 2 | Y8: 297803 | Z8: 1340051 | AA8: =W8-(Y8+Z8) -> 1504451 | AB8: 2638 | AC8: 1.14 | AD8: 0 | AE8: 0 | AF8: 2638 | AG8: 0.002 | AH8: 0.045 | AI8: 1.087 | AJ8: 2996151 | AK8: 2 | AL8: 296297 | AM8: 1263555 | AN8: =AJ8-(AL8+AM8) -> 1436299
A9: RP_ICR_N-100_I-3_R-0.95 | B9: 2428 | C9: 0.091 | D9: 2427 | E9: 0.001 | F9: 2428 | G9: 0.002 | H9: 0.016 | I9: 0.066 | J9: 368999 | K9: 2 | L9: 38255 | M9: 160054 | N9: =J9-(L9+M9) -> 170690 | O9: 2428 | P9: 0.078 | Q9: 2427 | R9: 0.001 | S9: 0 | T9: 0.002 | U9: 0 | V9: 0.069 | W9: 385814 | X9: 2 | Y9: 38885 | Z9: 168363 | AA9: =W9-(Y9+Z9) -> 178566 | AB9: 2428 | AC9: 0.096 | AD9: 0 | AE9: 0 | AF9: 2428 | AG9: 0.002 | AH9: 0.023 | AI9: 0.066 | AJ9: 368999 | AK9: 2 | AL9: 38255 | AM9: 160054 | AN9: =AJ9-(AL9+AM9) -> 170690
A10: RP_ICR_N-100_I-3_R-0.99 | B10: 2287 | C10: 0.816 | D10: 2245 | E10: 0.001 | F10: 2287 | G10: 0.002 | H10: 0.037 | I10: 0.77 | J10: 2378287 | K10: 2 | L10: 201900 | M10: 1036366 | N10: =J10-(L10+M10) -> 1140021 | O10: 2287 | P10: 0.836 | Q10: 2245 | R10: 0.001 | S10: 0 | T10: 0.002 | U10: 0 | V10: 0.828 | W10: 2534658 | X10: 2 | Y10: 202028 | Z10: 1120752 | AA10: =W10-(Y10+Z10) -> 1211878 | AB10: 2287 | AC10: 0.815 | AD10: 0 | AE10: 0 | AF10: 2287 | AG10: 0.002 | AH10: 0.037 | AI10: 0.77 | AJ10: 2378287 | AK10: 2 | AL10: 201900 | AM10: 1036366 | AN10: =AJ10-(AL10+AM10) -> 1140021
A11: RP_ICR_N-100_I-4_R-0.95 | B11: 2557 | C11: 0.098 | D11: 2513 | E11: 0.001 | F11: 2557 | G11: 0.002 | H11: 0.019 | I11: 0.07 | J11: 369315 | K11: 2 | L11: 36205 | M11: 163055 | N11: =J11-(L11+M11) -> 170055 | O11: 2557 | P11: 0.229 | Q11: 2513 | R11: 0.001 | S11: 0 | T11: 0.002 | U11: 0 | V11: 0.221 | W11: 879531 | X11: 2 | Y11: 58073 | Z11: 410940 | AA11: =W11-(Y11+Z11) -> 410518 | AB11: 2557 | AC11: 0.1 | AD11: 0 | AE11: 0 | AF11: 2557 | AG11: 0.002 | AH11: 0.021 | AI11: 0.07 | AJ11: 369315 | AK11: 2 | AL11: 36205 | AM11: 163055 | AN11: =AJ11-(AL11+AM11) -> 170055
A12: RP_ICR_N-100_I-4_R-0.99 | B12: 2422 | C12: 0.837 | D12: 2366 | E12: 0.001 | F12: 2422 | G12: 0.002 | H12: 0.034 | I12: 0.792 | J12: 2365951 | K12: 2 | L12: 226574 | M12: 1008339 | N12: =J12-(L12+M12) -> 1131038 | O12: 2422 | P12: 1.013 | Q12: 2366 | R12: 0.001 | S12: 0 | T12: 0.002 | U12: 0 | V12: 1.004 | W12: 2744333 | X12: 2 | Y12: 230182 | Z12: 1209075 | AA12: =W12-(Y12+Z12) -> 1305076 | AB12: 2422 | AC12: 0.832 | AD12: 0 | AE12: 0 | AF12: 2422 | AG12: 0.002 | AH12: 0.034 | AI12: 0.79 | AJ12: 2365951 | AK12: 2 | AL12: 226574 | AM12: 1008339 | AN12: =AJ12-(AL12+AM12) -> 1131038
A13: RP_ICR_N-400_I-0_R-0.95 | B13: 10493 | C13: 2.435 | D13: 10488 | E13: 0.013 | F13: 10493 | G13: 0.038 | H13: 0.196 | I13: 2.18 | J13: 8130383 | K13: 2 | L13: 182555 | M13: 4009398 | N13: =J13-(L13+M13) -> 3938430 | O13: 10493 | P13: 2.514 | Q13: 10488 | R13: 0.013 | S13: 0 | T13: 0.038 | U13: 0 | V13: 2.458 | W13: 9072627 | X13: 2 | Y13: 194273 | Z13: 4478000 | AA13: =W13-(Y13+Z13) -> 4400354 | AB13: 10493 | AC13: 2.871 | AD13: 0 | AE13: 0 | AF13: 10493 | AG13: 0.038 | AH13: 0.624 | AI13: 2.202 | AJ13: 8130383 | AK13: 2 | AL13: 182555 | AM13: 4009398 | AN13: =AJ13-(AL13+AM13) -> 3938430
A14: RP_ICR_N-400_I-0_R-0.99 | B14: 10198 | C14: 49.399 | D14: 10149 | E14: 0.013 | F14: 10198 | G14: 0.038 | H14: 0.572 | I14: 48.768 | J14: 79571576 | K14: 2 | L14: 1761582 | M14: 38615858 | N14: =J14-(L14+M14) -> 39194136 | O14: 10198 | P14: 70.817 | Q14: 10149 | R14: 0.013 | S14: 0 | T14: 0.038 | U14: 0 | V14: 70.761 | W14: 101498403 | X14: 2 | Y14: 1924948 | Z14: 49562518 | AA14: =W14-(Y14+Z14) -> 50010937 | AB14: 10198 | AC14: 48.917 | AD14: 0 | AE14: 0 | AF14: 10198 | AG14: 0.038 | AH14: 0.721 | AI14: 48.153 | AJ14: 79571576 | AK14: 2 | AL14: 1761582 | AM14: 38615858 | AN14: =AJ14-(AL14+AM14) -> 39194136
... A115: RP_SCU_N-900_I-1_R-0.95 | B115: 27793 | C115: 191.962 | D115: 27351 | E115: 0.131 | F115: 27791 | G115: 0.171 | H115: 16.19 | I115: 175.464 | J115: 422737884 | K115: 374 | L115: 811447 | M115: 211447457 | N115: =J115-(L115+M115) -> 210478980 | O115: 27793 | P115: 309.473 | Q115: 27351 | R115: 0.131 | S115: 0 | T115: 0.171 | U115: 0 | V115: 309.164 | W115: 593610267 | X115: 374 | Y115: 689214 | Z115: 297102561 | AA115: =W115-(Y115+Z115) -> 295818492 | AB115: 27793 | AC115: 195.12 | AD115: 0 | AE115: 0 | AF115: 27791 | AG115: 0.172 | AH115: 17.531 | AI115: 177.413 | AJ115: 422737884 | AK115: 374 | AL115: 811447 | AM115: 211447457 | AN115: =AJ115-(AL115+AM115) -> 210478980
A116: RP_SCU_N-900_I-1_R-0.99 | B116: OOM | C116: 3600 | O116: OOM | P116: 3600 | AB116: OOM | AC116: 3600
A117: RP_SCU_N-900_I-2_R-0.95 | B117: 28326 | C117: 182.677 | D117: 27753 | E117: 0.065 | F117: 28325 | G117: 0.175 | H117: 17.57 | I117: 164.859 | J117: 388224625 | K117: 309 | L117: 637227 | M117: 194252916 | N117: =J117-(L117+M117) -> 193334482 | O117: 28326 | P117: 317.248 | Q117: 27753 | R117: 0.065 | S117: 0 | T117: 0.175 | U117: 0 | V117: 316.999 | W117: 566059609 | X117: 309 | Y117: 517432 | Z117: 283381379 | AA117: =W117-(Y117+Z117) -> 282160798 | AB117: 28326 | AC117: 181.04 | AD117: 0 | AE117: 0 | AF117: 28325 | AG117: 0.175 | AH117: 18.265 | AI117: 162.591 | AJ117: 388224625 | AK117: 309 | AL117: 637227 | AM117: 194252916 | AN117: =AJ117-(AL117+AM117) -> 193334482
A118: RP_SCU_N-900_I-2_R-0.99 | B118: 27380 | C118: 1906.12 | D118: 27097 | E118: 0.061 | F118: 27376 | G118: 0.175 | H118: 17.709 | I118: 1888.17 | J118: 1443528559 | K118: 676 | L118: 3373248 | M118: 720906803 | N118: =J118-(L118+M118) -> 719248508 | O118: 27380 | P118: 2057.68 | Q118: 27097 | R118: 0.061 | S118: 0 | T118: 0.175 | U118: 0 | V118: 2057.44 | W118: 1512849528 | X118: 676 | Y118: 2935156 | Z118: 755952996 | AA118: =W118-(Y118+Z118) -> 753961376 | AB118: 27380 | AC118: 1923.15 | AD118: 0 | AE118: 0 | AF118: 27376 | AG118: 0.176 | AH118: 18.078 | AI118: 1904.89 | AJ118: 1443528559 | AK118: 676 | AL118: 3373248 | AM118: 720906803 | AN118: =AJ118-(AL118+AM118) -> 719248508
A119: RP_SCU_N-900_I-3_R-0.95 | B119: 27810 | C119: 186.01 | D119: 27378 | E119: 0.125 | F119: 27807 | G119: 0.171 | H119: 15.729 | I119: 169.975 | J119: 408217248 | K119: 293 | L119: 697953 | M119: 204239088 | N119: =J119-(L119+M119) -> 203280207 | O119: 27810 | P119: 277.289 | Q119: 27378 | R119: 0.125 | S119: 0 | T119: 0.171 | U119: 0 | V119: 276.985 | W119: 554036770 | X119: 293 | Y119: 592137 | Z119: 277322329 | AA119: =W119-(Y119+Z119) -> 276122304 | AB119: 27810 | AC119: 186.015 | AD119: 0 | AE119: 0 | AF119: 27807 | AG119: 0.171 | AH119: 16.62 | AI119: 169.217 | AJ119: 408217248 | AK119: 293 | AL119: 697953 | AM119: 204239088 | AN119: =AJ119-(AL119+AM119) -> 203280207
A120: RP_SCU_N-900_I-3_R-0.99 | B120: 26895 | C120: 2344.17 | D120: 26641 | E120: 0.061 | F120: 26892 | G120: 0.171 | H120: 16.93 | I120: 2327 | J120: 1593665192 | K120: 546 | L120: 3806188 | M120: 795653864 | N120: =J120-(L120+M120) -> 794205140 | O120: 26895 | P120: 2583.46 | Q120: 26641 | R120: 0.061 | S120: 0 | T120: 0.172 | U120: 0 | V120: 2583.22 | W120: 1685208466 | X120: 546 | Y120: 3322696 | Z120: 841862138 | AA120: =W120-(Y120+Z120) -> 840023632 | AB120: 26895 | AC120: 2357.61 | AD120: 0 | AE120: 0 | AF120: 26892 | AG120: 0.172 | AH120: 17.488 | AI120: 2339.95 | AJ120: 1593665192 | AK120: 546 | AL120: 3806188 | AM120: 795653864 | AN120: =AJ120-(AL120+AM120) -> 794205140
A121: RP_SCU_N-900_I-4_R-0.95 | B121: 28626 | C121: 183.159 | D121: 27827 | E121: 0.06 | F121: 28624 | G121: 0.177 | H121: 17.108 | I121: 165.805 | J121: 400796955 | K121: 379 | L121: 657243 | M121: 200588900 | N121: =J121-(L121+M121) -> 199550812 | O121: 28626 | P121: 354.831 | Q121: 27827 | R121: 0.06 | S121: 0 | T121: 0.177 | U121: 0 | V121: 354.586 | W121: 606835049 | X121: 379 | Y121: 520350 | Z121: 303841409 | AA121: =W121-(Y121+Z121) -> 302473290 | AB121: 28626 | AC121: 181.384 | AD121: 0 | AE121: 0 | AF121: 28624 | AG121: 0.177 | AH121: 17.761 | AI121: 163.437 | AJ121: 400796955 | AK121: 379 | AL121: 657243 | AM121: 200588900 | AN121: =AJ121-(AL121+AM121) -> 199550812
A122: RP_SCU_N-900_I-4_R-0.99 | B122: 27615 | C122: 2252.09 | D122: 27354 | E122: 0.06 | F122: 27609 | G122: 0.177 | H122: 17.234 | I122: 2234.62 | J122: 1603797317 | K122: 737 | L122: 3345660 | M122: 801266512 | N122: =J122-(L122+M122) -> 799185145 | O122: 27615 | P122: 2419.31 | Q122: 27354 | R122: 0.06 | S122: 0 | T122: 0.177 | U122: 0 | V122: 2419.07 | W122: 1664945601 | X122: 737 | Y122: 2795323 | Z122: 832304173 | AA122: =W122-(Y122+Z122) -> 829846105 | AB122: 27615 | AC122: 2294.73 | AD122: 0 | AE122: 0 | AF122: 27609 | AG122: 0.177 | AH122: 17.776 | AI122: 2276.77 | AJ122: 1603797317 | AK122: 737 | AL122: 3345660 | AM122: 801266512 | AN122: =AJ122-(AL122+AM122) -> 799185145
A123: RP_SC_N-100_I-0_R-0.95 | B123: 3196 | C123: 0.151 | D123: 3144 | E123: 0.001 | F123: 3196 | G123: 0.002 | H123: 0.038 | I123: 0.105 | J123: 717146 | K123: 8 | L123: 60644 | M123: 312512 | N123: =J3-(L3+M3) -> 157304 | O123: 3196 | P123: 0.281 | Q123: 3144 | R123: 0.001 | S123: 0 | T123: 0.002 | U123: 0 | V123: 0.273 | W123: 1470107 | X123: 8 | Y123: 83874 | Z123: 676162 | AA123: =W3-(Y3+Z3) -> 263037 | AB123: 3196 | AC123: 0.163 | AD123: 0 | AE123: 0 | AF123: 3196 | AG123: 0.002 | AH123: 0.049 | AI123: 0.106 | AJ123: 717146 | AK123: 8 | AL123: 60644 | AM123: 312512 | AN123: =AJ3-(AL3+AM3) -> 157304
A124: RP_SC_N-100_I-0_R-0.99 | B124: 3047 | C124: 1.789 | D124: 3044 | E124: 0.001 | F124: 3047 | G124: 0.002 | H124: 0.08 | I124: 1.7 | J124: 5785349 | K124: 298 | L124: 441989 | M124: 2503325 | N124: =J124-(L124+M124) -> 2840035 | O124: 3047 | P124: 1.733 | Q124: 3044 | R124: 0.001 | S124: 0 | T124: 0.002 | U124: 0 | V124: 1.725 | W124: 5871328 | X124: 298 | Y124: 442796 | Z124: 2546627 | AA124: =W124-(Y124+Z124) -> 2881905 | AB124: 3047 | AC124: 1.795 | AD124: 0 | AE124: 0 | AF124: 3047 | AG124: 0.002 | AH124: 0.084 | AI124: 1.703 | AJ124: 5785349 | AK124: 298 | AL124: 441989 | AM124: 2503325 | AN124: =AJ124-(AL124+AM124) -> 2840035
A125: RP_SC_N-100_I-1_R-0.95 | B125: 2952 | C125: 0.13 | D125: 2915 | E125: 0.001 | F125: 2952 | G125: 0.002 | H125: 0.031 | I125: 0.09 | J125: 608878 | K125: 143 | L125: 54514 | M125: 261460 | N125: =J125-(L125+M125) -> 292904 | O125: 2952 | P125: 0.203 | Q125: 2915 | R125: 0.001 | S125: 0 | T125: 0.002 | U125: 0 | V125: 0.195 | W125: 1095739 | X125: 143 | Y125: 70722 | Z125: 496474 | AA125: =W125-(Y125+Z125) -> 528543 | AB125: 2952 | AC125: 0.141 | AD125: 0 | AE125: 0 | AF125: 2952 | AG125: 0.002 | AH125: 0.043 | AI125: 0.091 | AJ125: 608878 | AK125: 143 | AL125: 54514 | AM125: 261460 | AN125: =AJ125-(AL125+AM125) -> 292904
A126: RP_SC_N-100_I-1_R-0.99 | B126: 2821 | C126: 1.25 | D126: 2787 | E126: 0.001 | F126: 2821 | G126: 0.002 | H126: 0.066 | I126: 1.175 | J126: 4311161 | K126: 309 | L126: 441676 | M126: 1757710 | N126: =J126-(L126+M126) -> 2111775 | O126: 2821 | P126: 1.544 | Q126: 2787 | R126: 0.001 | S126: 0 | T126: 0.002 | U126: 0 | V126: 1.536 | W126: 5087589 | X126: 309 | Y126: 460003 | Z126: 2137759 | AA126: =W126-(Y126+Z126) -> 2489827 | AB126: 2821 | AC126: 1.255 | AD126: 0 | AE126: 0 | AF126: 2821 | AG126: 0.002 | AH126: 0.07 | AI126: 1.177 | AJ126: 4311161 | AK126: 309 | AL126: 441676 | AM126: 1757710 | AN126: =AJ126-(AL126+AM126) -> 2111775
A127: RP_SC_N-100_I-2_R-0.95 | B127: 3165 | C127: 0.245 | D127: 3126 | E127: 0.001 | F127: 3165 | G127: 0.002 | H127: 0.049 | I127: 0.188 | J127: 1238497 | K127: 262 | L127: 120062 | M127: 514426 | N127: =J127-(L127+M127) -> 604009 | O127: 3165 | P127: 0.364 | Q127: 3126 | R127: 0.001 | S127: 0 | T127: 0.002 | U127: 0 | V127: 0.356 | W127: 1907562 | X127: 262 | Y127: 142280 | Z127: 836774 | AA127: =W127-(Y127+Z127) -> 928508 | AB127: 3165 | AC127: 0.258 | AD127: 0 | AE127: 0 | AF127: 3165 | AG127: 0.002 | AH127: 0.06 | AI127: 0.19 | AJ127: 1238497 | AK127: 262 | AL127: 120062 | AM127: 514426 | AN127: =AJ127-(AL127+AM127) -> 604009
A128: RP_SC_N-100_I-2_R-0.99 | B128: 3017 | C128: 2.303 | D128: 2952 | E128: 0.001 | F128: 3017 | G128: 0.002 | H128: 0.079 | I128: 2.216 | J128: 6732251 | K128: 396 | L128: 478530 | M128: 2947231 | N128: =J128-(L128+M128) -> 3306490 | O128: 3017 | P128: 2.987 | Q128: 2952 | R128: 0.001 | S128: 0 | T128: 0.002 | U128: 0 | V128: 2.978 | W128: 8132455 | X128: 396 | Y128: 484890 | Z128: 3661615 | AA128: =W128-(Y128+Z128) -> 3985950 | AB128: 3017 | AC128: 2.303 | AD128: 0 | AE128: 0 | AF128: 3017 | AG128: 0.002 | AH128: 0.081 | AI128: 2.215 | AJ128: 6732251 | AK128: 396 | AL128: 478530 | AM128: 2947231 | AN128: =AJ128-(AL128+AM128) -> 3306490
A129: RP_SC_N-100_I-3_R-0.95 | B129: 3101 | C129: 0.124 | D129: 3091 | E129: 0.001 | F129: 3101 | G129: 0.002 | H129: 0.03 | I129: 0.085 | J129: 631067 | K129: 88 | L129: 81334 | M129: 245465 | N129: =J129-(L129+M129) -> 304268 | O129: 3101 | P129: 0.116 | Q129: 3091 | R129: 0.001 | S129: 0 | T129: 0.002 | U129: 0 | V129: 0.108 | W129: 759839 | X129: 88 | Y129: 86130 | Z129: 307850 | AA129: =W129-(Y129+Z129) -> 365859 | AB129: 3101 | AC129: 0.143 | AD129: 0 | AE129: 0 | AF129: 3101 | AG129: 0.002 | AH129: 0.047 | AI129: 0.086 | AJ129: 631067 | AK129: 88 | AL129: 81334 | AM129: 245465 | AN129: =AJ129-(AL129+AM129) -> 304268
A130: RP_SC_N-100_I-3_R-0.99 | B130: 2964 | C130: 1.246 | D130: 2938 | E130: 0.001 | F130: 2964 | G130: 0.002 | H130: 0.07 | I130: 1.166 | J130: 4443837 | K130: 320 | L130: 481957 | M130: 1783740 | N130: =J130-(L130+M130) -> 2178140 | O130: 2964 | P130: 1.415 | Q130: 2938 | R130: 0.001 | S130: 0 | T130: 0.002 | U130: 0 | V130: 1.407 | W130: 5047338 | X130: 320 | Y130: 496561 | Z130: 2079703 | AA130: =W130-(Y130+Z130) -> 2471074 | AB130: 2964 | AC130: 1.241 | AD130: 0 | AE130: 0 | AF130: 2964 | AG130: 0.002 | AH130: 0.075 | AI130: 1.159 | AJ130: 4443837 | AK130: 320 | AL130: 481957 | AM130: 1783740 | AN130: =AJ130-(AL130+AM130) -> 2178140
A131: RP_SC_N-100_I-4_R-0.95 | B131: 3043 | C131: 0.245 | D131: 2984 | E131: 0.001 | F131: 3043 | G131: 0.002 | H131: 0.046 | I131: 0.189 | J131: 1211862 | K131: 101 | L131: 120671 | M131: 501992 | N131: =J131-(L131+M131) -> 589199 | O131: 3043 | P131: 0.431 | Q131: 2984 | R131: 0.001 | S131: 0 | T131: 0.002 | U131: 0 | V131: 0.422 | W131: 2034870 | X131: 101 | Y131: 147999 | Z131: 899498 | AA131: =W131-(Y131+Z131) -> 987373 | AB131: 3043 | AC131: 0.252 | AD131: 0 | AE131: 0 | AF131: 3043 | AG131: 0.002 | AH131: 0.054 | AI131: 0.19 | AJ131: 1211862 | AK131: 101 | AL131: 120671 | AM131: 501992 | AN131: =AJ131-(AL131+AM131) -> 589199
A132: RP_SC_N-100_I-4_R-0.99 | B132: 2895 | C132: 2.248 | D132: 2871 | E132: 0.001 | F132: 2895 | G132: 0.002 | H132: 0.071 | I132: 2.165 | J132: 6404288 | K132: 288 | L132: 447342 | M132: 2813355 | N132: =J132-(L132+M132) -> 3143591 | O132: 2895 | P132: 2.425 | Q132: 2871 | R132: 0.001 | S132: 0 | T132: 0.002 | U132: 0 | V132: 2.416 | W132: 6878826 | X132: 288 | Y132: 446654 | Z132: 3059172 | AA132: =W132-(Y132+Z132) -> 3373000 | AB132: 2895 | AC132: 2.248 | AD132: 0 | AE132: 0 | AF132: 2895 | AG132: 0.002 | AH132: 0.074 | AI132: 2.167 | AJ132: 6404288 | AK132: 288 | AL132: 447342 | AM132: 2813355 | AN132: =AJ132-(AL132+AM132) -> 3143591
A133: RP_SC_N-400_I-0_R-0.95 | B133: 13027 | C133: 3.258 | D133: 12942 | E133: 0.013 | F133: 13027 | G133: 0.036 | H133: 0.428 | I133: 2.775 | J133: 13413511 | K133: 133 | L133: 377498 | M133: 6435153 | N133: =J133-(L133+M133) -> 6600860 | O133: 13027 | P133: 6.654 | Q133: 12942 | R133: 0.013 | S133: 0 | T133: 0.036 | U133: 0 | V133: 6.599 | W133: 25696250 | X133: 133 | Y133: 494431 | Z133: 12524046 | AA133: =W133-(Y133+Z133) -> 12677773 | AB133: 13027 | AC133: 3.597 | AD133: 0 | AE133: 0 | AF133: 13027 | AG133: 0.036 | AH133: 0.764 | AI133: 2.792 | AJ133: 13413511 | AK133: 133 | AL133: 377498 | AM133: 6435153 | AN133: =AJ133-(AL133+AM133) -> 6600860
A134: RP_SC_N-400_I-0_R-0.99 | B134: 12701 | C134: 52.497 | D134: 12607 | E134: 0.013 | F134: 12701 | G134: 0.036 | H134: 0.978 | I134: 51.462 | J134: 121179863 | K134: 304 | L134: 3237716 | M134: 57793898 | N134: =J134-(L134+M134) -> 60148249 | O134: 12701 | P134: 73.974 | Q134: 12607 | R134: 0.013 | S134: 0 | T134: 0.036 | U134: 0 | V134: 73.917 | W134: 150665145 | X134: 304 | Y134: 3512048 | Z134: 72379934 | AA134: =W134-(Y134+Z134) -> 74773163 | AB134: 12701 | AC134: 52.221 | AD134: 0 | AE134: 0 | AF134: 12701 | AG134: 0.036 | AH134: 1.236 | AI134: 50.943 | AJ134: 121179863 | AK134: 304 | AL134: 3237716 | AM134: 57793898 | AN134: =AJ134-(AL134+AM134) -> 60148249
A135: RP_SC_N-400_I-1_R-0.95 | B135: 12424 | C135: 1.573 | D135: 12404 | E135: 0.013 | F135: 12424 | G135: 0.034 | H135: 0.263 | I135: 1.256 | J135: 7626279 | K135: 71 | L135: 268910 | M135: 3619135 | N135: =J135-(L135+M135) -> 3738234 | O135: 12424 | P135: 1.898 | Q135: 12404 | R135: 0.013 | S135: 0 | T135: 0.034 | U135: 0 | V135: 1.845 | W135: 9919241 | X135: 71 | Y135: 287842 | Z135: 4761475 | AA135: =W135-(Y135+Z135) -> 4869924 | AB135: 12424 | AC135: 1.982 | AD135: 0 | AE135: 0 | AF135: 12424 | AG135: 0.034 | AH135: 0.664 | AI135: 1.278 | AJ135: 7626279 | AK135: 71 | AL135: 268910 | AM135: 3619135 | AN135: =AJ135-(AL135+AM135) -> 3738234
... A172: RP_SS_N-400_I-4_R-0.99 | B172: 9158 | C172: 896.278 | D172: 9084 | E172: 0.022 | F172: 9158 | G172: 0.032 | H172: 6.829 | I172: 889.387 | J172: 745536097 | K172: 1626903 | L172: 2000017 | M172: 369140863 | N172: =J172-(L172+M172) -> 374395217 | O172: 9158 | P172: 991.292 | Q172: 9084 | R172: 0.022 | S172: 0 | T172: 0.033 | U172: 0 | V172: 991.232 | W172: 821816924 | X172: 1631875 | Y172: 2050294 | Z172: 407365303 | AA172: =W172-(Y172+Z172) -> 412401327 | AB172: 9158 | AC172: 902.326 | AD172: 0 | AE172: 0 | AF172: 9158 | AG172: 0.032 | AH172: 6.942 | AI172: 895.348 | AJ172: 745536097 | AK172: 1626903 | AL172: 2000017 | AM172: 369140863 | AN172: =AJ172-(AL172+AM172) -> 374395217
A173: RP_SS_N-900_I-0_R-0.95 | B173: 22810 | C173: 2382.86 | D173: 22768 | E173: 0.071 | F173: 22810 | G173: 0.173 | H173: 36.528 | I173: 2346.08 | K173: 2748926 | L173: 1713786 | M173: 1357139896 | O173: 22810 | P173: 2609.61 | Q173: 22768 | R173: 0.071 | S173: 0 | T173: 0.173 | U173: 0 | V173: 2609.36 | X173: 2748926 | Y173: 1758099 | Z173: 1465861548 | AB173: 22810 | AC173: 2443.19 | AD173: 0 | AE173: 0 | AF173: 22810 | AG173: 0.173 | AH173: 37.554 | AI173: 2405.46 | AK173: 2748926 | AL173: 1713786 | AM173: 1357139896
A174: RP_SS_N-900_I-0_R-0.99 | B174: 22247 | C174: 3600 | D174: 22197 | E174: 0.118 | F174: 22247 | G174: 0.173 | H174: 41.202 | I174: 3576.76 | K174: 4354465 | L174: 1445532 | M174: 1157523993 | O174: 22197 | P174: 3600 | Q174: 22197 | R174: 0.118 | S174: 0 | T174: 0.173 | U174: 0 | V174: 3600 | X174: 4701981 | Y174: 1213790 | Z174: 1215907238 | AB174: 22247 | AC174: 3600 | AD174: 0 | AE174: 0 | AF174: 22247 | AG174: 0.173 | AH174: 43.715 | AI174: 3568.38 | AK174: 4338081 | AL174: 1417777 | AM174: 1144544034
A175: RP_SS_N-900_I-1_R-0.95 | B175: 22355 | C175: 2284.09 | D175: 22314 | E175: 0.098 | F175: 22355 | G175: 0.17 | H175: 35.811 | I175: 2248 | K175: 2622320 | L175: 1707729 | M175: 1301960256 | O175: 22355 | P175: 2377.06 | Q175: 22314 | R175: 0.098 | S175: 0 | T175: 0.17 | U175: 0 | V175: 2376.79 | X175: 2622320 | Y175: 1625148 | Z175: 1403820677 | AB175: 22355 | AC175: 2289.8 | AD175: 0 | AE175: 0 | AF175: 22355 | AG175: 0.17 | AH175: 36.712 | AI175: 2252.91 | AK175: 2622320 | AL175: 1707729 | AM175: 1301960256
A176: RP_SS_N-900_I-1_R-0.99 | B176: 21802 | C176: 3600 | D176: 21732 | E176: 0.146 | F176: 21802 | G176: 0.17 | H176: 41.423 | I176: 3567.71 | K176: 4354254 | L176: 1605514 | M176: 1215242078 | O176: 21732 | P176: 3600 | Q176: 21732 | R176: 0.146 | S176: 0 | T176: 0.17 | U176: 0 | V176: 3600 | X176: 4801909 | Y176: 1024305 | Z176: 1242189156 | AB176: 21802 | AC176: 3600 | AD176: 0 | AE176: 0 | AF176: 21802 | AG176: 0.17 | AH176: 42.251 | AI176: 3565.98 | AK176: 4333938 | AL176: 1510727 | AM176: 1193639480
...

Sheet theta=1
A1: Filename | B1: 1-def | O1: 3-maskHLA | AB1: 4-maskTS
B2: My_Obj_Val | C2: My_Time_s | D2: My_TS_Val | E2: my_TSTime | F2: My_HLA_Val | G2: my_fracKPTime | H2: My_HLATime | I2: My_exactTime | J2: my_labelNum | K2: my_nonlabelNum | L2: my_CBfathomedlabelNum | M2: my_dominatedlabelNum | N2: non_dominated | O2: My_Obj_Val | P2: My_Time_s | Q2: My_TS_Val | R2: my_TSTime | S2: My_HLA_Val | T2: my_fracKPTime | U2: My_HLATime | V2: My_exactTime | W2: my_labelNum | X2: my_nonlabelNum | Y2: my_CBfathomedlabelNum | Z2: my_dominatedlabelNum | AA2: non-dominated | AB2: My_Obj_Val | AC2: My_Time_s | AD2: My_TS_Val | AE2: my_TSTime | AF2: My_HLA_Val | AG2: my_fracKPTime | AH2: My_HLATime | AI2: My_exactTime | AJ2: my_labelNum | AK2: my_nonlabelNum | AL2: my_CBfathomedlabelNum | AM2: my_dominatedlabelNum | AN2: non-dominated
A3: RP_ICR_N-100_I-0_R-0.95 | B3: 2804 | C3: 0.043 | D3: 2783 | E3: 0.001 | F3: 2804 | G3: 0.002 | H3: 0.01 | I3: 0.024 | J3: 141762 | K3: 2 | L3: 15919 | M3: 56573 | N3: =J3-(L3+M3) -> 69270 | O3: 2804 | P3: 0.045 | Q3: 2783 | R3: 0.001 | S3: 0 | T3: 0.002 | U3: 0 | V3: 0.039 | W3: 215856 | X3: 2 | Y3: 18808 | Z3: 92780 | AA3: =W3-(Y3+Z3) -> 104268 | AB3: 2804 | AC3: 0.044 | AD3: 0 | AE3: 0 | AF3: 2804 | AG3: 0.002 | AH3: 0.013 | AI3: 0.024 | AJ3: 141762 | AK3: 2 | AL3: 15919 | AM3: 56573 | AN3: =AJ3-(AL3+AM3) -> 69270
A4: RP_ICR_N-100_I-0_R-0.99 | B4: 2672 | C4: 0.179 | D4: 2641 | E4: 0.001 | F4: 2672 | G4: 0.002 | H4: 0.015 | I4: 0.154 | J4: 680604 | K4: 2 | L4: 80726 | M4: 274443 | N4: =J4-(L4+M4) -> 325435 | O4: 2672 | P4: 0.211 | Q4: 2641 | R4: 0.001 | S4: 0 | T4: 0.002 | U4: 0 | V4: 0.201 | W4: 813823 | X4: 2 | Y4: 80178 | Z4: 345043 | AA4: =W4-(Y4+Z4) -> 388602 | AB4: 2672 | AC4: 0.175 | AD4: 0 | AE4: 0 | AF4: 2672 | AG4: 0.002 | AH4: 0.016 | AI4: 0.154 | AJ4: 680604 | AK4: 2 | AL4: 80726 | AM4: 274443 | AN4: =AJ4-(AL4+AM4) -> 325435
A5: RP_ICR_N-100_I-1_R-0.95 | B5: 2767 | C5: 0.047 | D5: 2759 | E5: 0.001 | F5: 2767 | G5: 0.002 | H5: 0.009 | I5: 0.031 | J5: 171250 | K5: 2 | L5: 18283 | M5: 70998 | N5: =J5-(L5+M5) -> 81969 | O5: 2767 | P5: 0.051 | Q5: 2759 | R5: 0.001 | S5: 0 | T5: 0.002 | U5: 0 | V5: 0.042 | W5: 218064 | X5: 2 | Y5: 19566 | Z5: 94569 | AA5: =W5-(Y5+Z5) -> 103929 | AB5: 2767 | AC5: 0.049 | AD5: 0 | AE5: 0 | AF5: 2767 | AG5: 0.002 | AH5: 0.011 | AI5: 0.031 | AJ5: 171250 | AK5: 2 | AL5: 18283 | AM5: 70998 | AN5: =AJ5-(AL5+AM5) -> 81969
A6: RP_ICR_N-100_I-1_R-0.99 | B6: 2633 | C6: 0.261 | D6: 2598 | E6: 0.001 | F6: 2633 | G6: 0.002 | H6: 0.017 | I6: 0.235 | J6: 871983 | K6: 2 | L6: 88277 | M6: 366423 | N6: =J6-(L6+M6) -> 417283 | O6: 2633 | P6: 0.329 | Q6: 2598 | R6: 0.001 | S6: 0 | T6: 0.002 | U6: 0 | V6: 0.32 | W6: 1043664 | X6: 2 | Y6: 88456 | Z6: 457000 | AA6: =W6-(Y6+Z6) -> 498208 | AB6: 2633 | AC6: 0.257 | AD6: 0 | AE6: 0 | AF6: 2633 | AG6: 0.002 | AH6: 0.017 | AI6: 0.235 | AJ6: 871983 | AK6: 2 | AL6: 88277 | AM6: 366423 | AN6: =AJ6-(AL6+AM6) -> 417283
A7: RP_ICR_N-100_I-2_R-0.95 | B7: 2778 | C7: 0.051 | D7: 2722 | E7: 0.001 | F7: 2778 | G7: 0.002 | H7: 0.011 | I7: 0.028 | J7: 155537 | K7: 2 | L7: 20294 | M7: 62017 | N7: =J7-(L7+M7) -> 73226 | O7: 2778 | P7: 0.085 | Q7: 2722 | R7: 0.001 | S7: 0 | T7: 0.002 | U7: 0 | V7: 0.076 | W7: 345770 | X7: 2 | Y7: 27695 | Z7: 155823 | AA7: =W7-(Y7+Z7) -> 162252 | AB7: 2778 | AC7: 0.047 | AD7: 0 | AE7: 0 | AF7: 2778 | AG7: 0.002 | AH7: 0.013 | AI7: 0.027 | AJ7: 155537 | AK7: 2 | AL7: 20294 | AM7: 62017 | AN7: =AJ7-(AL7+AM7) -> 73226
A8: RP_ICR_N-100_I-2_R-0.99 | B8: 2638 | C8: 0.357 | D8: 2631 | E8: 0.001 | F8: 2638 | G8: 0.002 | H8: 0.02 | I8: 0.328 | J8: 1132219 | K8: 2 | L8: 106468 | M8: 479179 | N8: =J8-(L8+M8) -> 546572 | O8: 2638 | P8: 0.354 | Q8: 2631 | R8: 0.001 | S8: 0 | T8: 0.002 | U8: 0 | V8: 0.345 | W8: 1177889 | X8: 2 | Y8: 106262 | Z8: 503653 | AA8: =W8-(Y8+Z8) -> 567974 | AB8: 2638 | AC8: 0.355 | AD8: 0 | AE8: 0 | AF8: 2638 | AG8: 0.002 | AH8: 0.02 | AI8: 0.329 | AJ8: 1132219 | AK8: 2 | AL8: 106468 | AM8: 479179 | AN8: =AJ8-(AL8+AM8) -> 546572
A9: RP_ICR_N-100_I-3_R-0.95 | B9: 2428 | C9: 0.045 | D9: 2427 | E9: 0.001 | F9: 2428 | G9: 0.002 | H9: 0.008 | I9: 0.029 | J9: 162623 | K9: 2 | L9: 15574 | M9: 70823 | N9: =J9-(L9+M9) -> 76226 | O9: 2428 | P9: 0.038 | Q9: 2427 | R9: 0.001 | S9: 0 | T9: 0.002 | U9: 0 | V9: 0.029 | W9: 168652 | X9: 2 | Y9: 15586 | Z9: 73979 | AA9: =W9-(Y9+Z9) -> 79087 | AB9: 2428 | AC9: 0.044 | AD9: 0 | AE9: 0 | AF9: 2428 | AG9: 0.002 | AH9: 0.01 | AI9: 0.028 | AJ9: 162623 | AK9: 2 | AL9: 15574 | AM9: 70823 | AN9: =AJ9-(AL9+AM9) -> 76226
A10: RP_ICR_N-100_I-3_R-0.99 | B10: 2287 | C10: 0.258 | D10: 2245 | E10: 0.001 | F10: 2287 | G10: 0.002 | H10: 0.016 | I10: 0.234 | J10: 905361 | K10: 2 | L10: 76095 | M10: 393291 | N10: =J10-(L10+M10) -> 435975 | O10: 2287 | P10: 0.255 | Q10: 2245 | R10: 0.001 | S10: 0 | T10: 0.002 | U10: 0 | V10: 0.248 | W10: 952947 | X10: 2 | Y10: 75524 | Z10: 419341 | AA10: =W10-(Y10+Z10) -> 458082 | AB10: 2287 | AC10: 0.255 | AD10: 0 | AE10: 0 | AF10: 2287 | AG10: 0.002 | AH10: 0.016 | AI10: 0.232 | AJ10: 905361 | AK10: 2 | AL10: 76095 | AM10: 393291 | AN10: =AJ10-(AL10+AM10) -> 435975
A11: RP_ICR_N-100_I-4_R-0.95 | B11: 2557 | C11: 0.043 | D11: 2513 | E11: 0.001 | F11: 2557 | G11: 0.002 | H11: 0.009 | I11: 0.028 | J11: 155076 | K11: 2 | L11: 15617 | M11: 67536 | N11: =J11-(L11+M11) -> 71923 | O11: 2557 | P11: 0.075 | Q11: 2513 | R11: 0.001 | S11: 0 | T11: 0.002 | U11: 0 | V11: 0.066 | W11: 316624 | X11: 2 | Y11: 21665 | Z11: 146466 | AA11: =W11-(Y11+Z11) -> 148493 | AB11: 2557 | AC11: 0.045 | AD11: 0 | AE11: 0 | AF11: 2557 | AG11: 0.002 | AH11: 0.01 | AI11: 0.028 | AJ11: 155076 | AK11: 2 | AL11: 15617 | AM11: 67536 | AN11: =AJ11-(AL11+AM11) -> 71923
A12: RP_ICR_N-100_I-4_R-0.99 | B12: 2422 | C12: 0.28 | D12: 2366 | E12: 0.001 | F12: 2422 | G12: 0.002 | H12: 0.014 | I12: 0.257 | J12: 934672 | K12: 2 | L12: 88824 | M12: 397606 | N12: =J12-(L12+M12) -> 448242 | O12: 2422 | P12: 0.319 | Q12: 2366 | R12: 0.001 | S12: 0 | T12: 0.002 | U12: 0 | V12: 0.311 | W12: 1046038 | X12: 2 | Y12: 88758 | Z12: 457358 | AA12: =W12-(Y12+Z12) -> 499922 | AB12: 2422 | AC12: 0.278 | AD12: 0 | AE12: 0 | AF12: 2422 | AG12: 0.002 | AH12: 0.014 | AI12: 0.257 | AJ12: 934672 | AK12: 2 | AL12: 88824 | AM12: 397606 | AN12: =AJ12-(AL12+AM12) -> 448242
A13: RP_ICR_N-400_I-0_R-0.95 | B13: 10493 | C13: 0.68 | D13: 10488 | E13: 0.013 | F13: 10493 | G13: 0.038 | H13: 0.104 | I13: 0.519 | J13: 2631726 | K13: 2 | L13: 72790 | M13: 1282128 | N13: =J13-(L13+M13) -> 1276808 | O13: 10493 | P13: 0.629 | Q13: 10488 | R13: 0.013 | S13: 0 | T13: 0.038 | U13: 0 | V13: 0.572 | W13: 2927520 | X13: 2 | Y13: 76112 | Z13: 1429360 | AA13: =W13-(Y13+Z13) -> 1422048 | AB13: 10493 | AC13: 0.754 | AD13: 0 | AE13: 0 | AF13: 10493 | AG13: 0.038 | AH13: 0.193 | AI13: 0.517 | AJ13: 2631726 | AK13: 2 | AL13: 72790 | AM13: 1282128 | AN13: =AJ13-(AL13+AM13) -> 1276808
A14: RP_ICR_N-400_I-0_R-0.99 | B14: 10198 | C14: 10.26 | D14: 10149 | E14: 0.013 | F14: 10198 | G14: 0.038 | H14: 0.213 | I14: 9.99 | J14: 25232422 | K14: 2 | L14: 596960 | M14: 12190590 | N14: =J14-(L14+M14) -> 12444872 | O14: 10198 | P14: 13.441 | Q14: 10149 | R14: 0.013 | S14: 0 | T14: 0.038 | U14: 0 | V14: 13.384 | W14: 30230866 | X14: 2 | Y14: 618918 | Z14: 14697862 | AA14: =W14-(Y14+Z14) -> 14914086 | AB14: 10198 | AC14: 10.311 | AD14: 0 | AE14: 0 | AF14: 10198 | AG14: 0.038 | AH14: 0.244 | AI14: 10.023 | AJ14: 25232422 | AK14: 2 | AL14: 596960 | AM14: 12190590 | AN14: =AJ14-(AL14+AM14) -> 12444872
... A122: RP_SCU_N-900_I-4_R-0.99 | B122: 27615 | C122: 275.682 | D122: 27354 | E122: 0.06 | F122: 27609 | G122: 0.177 | H122: 2.221 | I122: 273.217 | J122: 411257043 | K122: 459 | L122: 920123 | M122: 205394560 | N122: =J122-(L122+M122) -> 204942360 | O122: 27615 | P122: 280.827 | Q122: 27354 | R122: 0.06 | S122: 0 | T122: 0.177 | U122: 0 | V122: 280.582 | W122: 423779658 | X122: 459 | Y122: 747817 | Z122: 211788375 | AA122: =W122-(Y122+Z122) -> 211243466 | AB122: 27615 | AC122: 284.313 | AD122: 0 | AE122: 0 | AF122: 27609 | AG122: 0.177 | AH122: 2.413 | AI122: 281.715 | AJ122: 411257043 | AK122: 459 | AL122: 920123 | AM122: 205394560 | AN122: =AJ122-(AL122+AM122) -> 204942360
A123: RP_SC_N-100_I-0_R-0.95 | B123: 3196 | C123: 0.064 | D123: 3144 | E123: 0.001 | F123: 3196 | G123: 0.002 | H123: 0.015 | I123: 0.041 | J123: 295431 | K123: 8 | L123: 27959 | M123: 125062 | N123: =J3-(L3+M3) -> 69270 | O123: 3196 | P123: 0.092 | Q123: 3144 | R123: 0.001 | S123: 0 | T123: 0.002 | U123: 0 | V123: 0.083 | W123: 524765 | X123: 8 | Y123: 34419 | Z123: 236075 | AA123: =W3-(Y3+Z3) -> 104268 | AB123: 3196 | AC123: 0.065 | AD123: 0 | AE123: 0 | AF123: 3196 | AG123: 0.002 | AH123: 0.019 | AI123: 0.041 | AJ123: 295431 | AK123: 8 | AL123: 27959 | AM123: 125062 | AN123: =AJ3-(AL3+AM3) -> 69270
A124: RP_SC_N-100_I-0_R-0.99 | B124: 3047 | C124: 0.514 | D124: 3044 | E124: 0.001 | F124: 3047 | G124: 0.002 | H124: 0.028 | I124: 0.478 | J124: 2096952 | K124: 179 | L124: 150834 | M124: 914272 | N124: =J124-(L124+M124) -> 1031846 | O124: 3047 | P124: 0.488 | Q124: 3044 | R124: 0.001 | S124: 0 | T124: 0.002 | U124: 0 | V124: 0.48 | W124: 2120480 | X124: 179 | Y124: 150852 | Z124: 926324 | AA124: =W124-(Y124+Z124) -> 1043304 | AB124: 3047 | AC124: 0.514 | AD124: 0 | AE124: 0 | AF124: 3047 | AG124: 0.002 | AH124: 0.03 | AI124: 0.477 | AJ124: 2096952 | AK124: 179 | AL124: 150834 | AM124: 914272 | AN124: =AJ124-(AL124+AM124) -> 1031846
A125: RP_SC_N-100_I-1_R-0.95 | B125: 2952 | C125: 0.058 | D125: 2915 | E125: 0.001 | F125: 2952 | G125: 0.002 | H125: 0.013 | I125: 0.036 | J125: 253569 | K125: 94 | L125: 24353 | M125: 106057 | N125: =J125-(L125+M125) -> 123159 | O125: 2952 | P125: 0.071 | Q125: 2915 | R125: 0.001 | S125: 0 | T125: 0.002 | U125: 0 | V125: 0.062 | W125: 401937 | X125: 94 | Y125: 28768 | Z125: 177862 | AA125: =W125-(Y125+Z125) -> 195307 | AB125: 2952 | AC125: 0.058 | AD125: 0 | AE125: 0 | AF125: 2952 | AG125: 0.002 | AH125: 0.017 | AI125: 0.036 | AJ125: 253569 | AK125: 94 | AL125: 24353 | AM125: 106057 | AN125: =AJ125-(AL125+AM125) -> 123159
A126: RP_SC_N-100_I-1_R-0.99 | B126: 2821 | C126: 0.364 | D126: 2787 | E126: 0.001 | F126: 2821 | G126: 0.002 | H126: 0.023 | I126: 0.331 | J126: 1581418 | K126: 183 | L126: 162839 | M126: 641457 | N126: =J126-(L126+M126) -> 777122 | O126: 2821 | P126: 0.408 | Q126: 2787 | R126: 0.001 | S126: 0 | T126: 0.002 | U126: 0 | V126: 0.4 | W126: 1787323 | X126: 183 | Y126: 165715 | Z126: 743938 | AA126: =W126-(Y126+Z126) -> 877670 | AB126: 2821 | AC126: 0.366 | AD126: 0 | AE126: 0 | AF126: 2821 | AG126: 0.002 | AH126: 0.025 | AI126: 0.332 | AJ126: 1581418 | AK126: 183 | AL126: 162839 | AM126: 641457 | AN126: =AJ126-(AL126+AM126) -> 777122
A127: RP_SC_N-100_I-2_R-0.95 | B127: 3165 | C127: 0.102 | D127: 3126 | E127: 0.001 | F127: 3165 | G127: 0.002 | H127: 0.019 | I127: 0.076 | J127: 514737 | K127: 150 | L127: 46574 | M127: 215794 | N127: =J127-(L127+M127) -> 252369 | O127: 3165 | P127: 0.126 | Q127: 3126 | R127: 0.001 | S127: 0 | T127: 0.002 | U127: 0 | V127: 0.119 | W127: 725442 | X127: 150 | Y127: 52068 | Z127: 318328 | AA127: =W127-(Y127+Z127) -> 355046 | AB127: 3165 | AC127: 0.108 | AD127: 0 | AE127: 0 | AF127: 3165 | AG127: 0.002 | AH127: 0.023 | AI127: 0.077 | AJ127: 514737 | AK127: 150 | AL127: 46574 | AM127: 215794 | AN127: =AJ127-(AL127+AM127) -> 252369
A128: RP_SC_N-100_I-2_R-0.99 | B128: 3017 | C128: 0.659 | D128: 2952 | E128: 0.001 | F128: 3017 | G128: 0.002 | H128: 0.028 | I128: 0.621 | J128: 2418423 | K128: 219 | L128: 155797 | M128: 1072385 | N128: =J128-(L128+M128) -> 1190241 | O128: 3017 | P128: 0.811 | Q128: 2952 | R128: 0.001 | S128: 0 | T128: 0.002 | U128: 0 | V128: 0.803 | W128: 2793962 | X128: 219 | Y128: 151814 | Z128: 1269588 | AA128: =W128-(Y128+Z128) -> 1372560 | AB128: 3017 | AC128: 0.666 | AD128: 0 | AE128: 0 | AF128: 3017 | AG128: 0.002 | AH128: 0.03 | AI128: 0.631 | AJ128: 2418423 | AK128: 219 | AL128: 155797 | AM128: 1072385 | AN128: =AJ128-(AL128+AM128) -> 1190241
A129: RP_SC_N-100_I-3_R-0.95 | B129: 3101 | C129: 0.058 | D129: 3091 | E129: 0.001 | F129: 3101 | G129: 0.002 | H129: 0.013 | I129: 0.036 | J129: 275949 | K129: 68 | L129: 37453 | M129: 104450 | N129: =J129-(L129+M129) -> 134046 | O129: 3101 | P129: 0.052 | Q129: 3091 | R129: 0.001 | S129: 0 | T129: 0.002 | U129: 0 | V129: 0.044 | W129: 319256 | X129: 68 | Y129: 38494 | Z129: 125717 | AA129: =W129-(Y129+Z129) -> 155045 | AB129: 3101 | AC129: 0.064 | AD129: 0 | AE129: 0 | AF129: 3101 | AG129: 0.002 | AH129: 0.019 | AI129: 0.037 | AJ129: 275949 | AK129: 68 | AL129: 37453 | AM129: 104450 | AN129: =AJ129-(AL129+AM129) -> 134046
A130: RP_SC_N-100_I-3_R-0.99 | B130: 2964 | C130: 0.373 | D130: 2938 | E130: 0.001 | F130: 2964 | G130: 0.002 | H130: 0.025 | I130: 0.338 | J130: 1645275 | K130: 191 | L130: 173432 | M130: 662987 | N130: =J130-(L130+M130) -> 808856 | O130: 2964 | P130: 0.395 | Q130: 2938 | R130: 0.001 | S130: 0 | T130: 0.002 | U130: 0 | V130: 0.386 | W130: 1807147 | X130: 191 | Y130: 174717 | Z130: 744545 | AA130: =W130-(Y130+Z130) -> 887885 | AB130: 2964 | AC130: 0.374 | AD130: 0 | AE130: 0 | AF130: 2964 | AG130: 0.002 | AH130: 0.027 | AI130: 0.34 | AJ130: 1645275 | AK130: 191 | AL130: 173432 | AM130: 662987 | AN130: =AJ130-(AL130+AM130) -> 808856
A131: RP_SC_N-100_I-4_R-0.95 | B131: 3043 | C131: 0.099 | D131: 2984 | E131: 0.001 | F131: 3043 | G131: 0.002 | H131: 0.017 | I131: 0.073 | J131: 496065 | K131: 67 | L131: 50622 | M131: 203331 | N131: =J131-(L131+M131) -> 242112 | O131: 3043 | P131: 0.133 | Q131: 2984 | R131: 0.001 | S131: 0 | T131: 0.002 | U131: 0 | V131: 0.125 | W131: 733721 | X131: 67 | Y131: 56993 | Z131: 319139 | AA131: =W131-(Y131+Z131) -> 357589 | AB131: 3043 | AC131: 0.102 | AD131: 0 | AE131: 0 | AF131: 3043 | AG131: 0.002 | AH131: 0.02 | AI131: 0.074 | AJ131: 496065 | AK131: 67 | AL131: 50622 | AM131: 203331 | AN131: =AJ131-(AL131+AM131) -> 242112
A132: RP_SC_N-100_I-4_R-0.99 | B132: 2895 | C132: 0.653 | D132: 2871 | E132: 0.001 | F132: 2895 | G132: 0.002 | H132: 0.026 | I132: 0.618 | J132: 2304135 | K132: 180 | L132: 147231 | M132: 1023991 | N132: =J132-(L132+M132) -> 1132913 | O132: 2895 | P132: 0.678 | Q132: 2871 | R132: 0.001 | S132: 0 | T132: 0.002 | U132: 0 | V132: 0.67 | W132: 2426514 | X132: 180 | Y132: 144882 | Z132: 1089462 | AA132: =W132-(Y132+Z132) -> 1192170 | AB132: 2895 | AC132: 0.654 | AD132: 0 | AE132: 0 | AF132: 2895 | AG132: 0.002 | AH132: 0.027 | AI132: 0.62 | AJ132: 2304135 | AK132: 180 | AL132: 147231 | AM132: 1023991 | AN132: =AJ132-(AL132+AM132) -> 1132913
A133: RP_SC_N-400_I-0_R-0.95 | B133: 13027 | C133: 0.947 | D133: 12942 | E133: 0.013 | F133: 13027 | G133: 0.036 | H133: 0.178 | I133: 0.715 | J133: 4627592 | K133: 86 | L133: 163909 | M133: 2181880 | N133: =J133-(L133+M133) -> 2281803 | O133: 13027 | P133: 1.631 | Q133: 12942 | R133: 0.013 | S133: 0 | T133: 0.036 | U133: 0 | V133: 1.576 | W133: 8055355 | X133: 86 | Y133: 194418 | Z133: 3880694 | AA133: =W133-(Y133+Z133) -> 3980243 | AB133: 13027 | AC133: 1.052 | AD133: 0 | AE133: 0 | AF133: 13027 | AG133: 0.036 | AH133: 0.285 | AI133: 0.725 | AJ133: 4627592 | AK133: 86 | AL133: 163909 | AM133: 2181880 | AN133: =AJ133-(AL133+AM133) -> 2281803
A134: RP_SC_N-400_I-0_R-0.99 | B134: 12701 | C134: 14.261 | D134: 12607 | E134: 0.013 | F134: 12701 | G134: 0.036 | H134: 0.299 | I134: 13.906 | J134: 41956871 | K134: 171 | L134: 1139165 | M134: 19974182 | N134: =J134-(L134+M134) -> 20843524 | O134: 12701 | P134: 17.792 | Q134: 12607 | R134: 0.013 | S134: 0 | T134: 0.036 | U134: 0 | V134: 17.737 | W134: 49269519 | X134: 171 | Y134: 1197054 | Z134: 23600071 | AA134: =W134-(Y134+Z134) -> 24472394 | AB134: 12701 | AC134: 14.366 | AD134: 0 | AE134: 0 | AF134: 12701 | AG134: 0.036 | AH134: 0.369 | AI134: 13.954 | AJ134: 41956871 | AK134: 171 | AL134: 1139165 | AM134: 19974182 | AN134: =AJ134-(AL134+AM134) -> 20843524
A135: RP_SC_N-400_I-1_R-0.95 | B135: 12424 | C135: 0.553 | D135: 12404 | E135: 0.013 | F135: 12424 | G135: 0.034 | H135: 0.128 | I135: 0.371 | J135: 2677648 | K135: 50 | L135: 113616 | M135: 1247047 | N135: =J135-(L135+M135) -> 1316985 | O135: 12424 | P135: 0.529 | Q135: 12404 | R135: 0.013 | S135: 0 | T135: 0.034 | U135: 0 | V135: 0.476 | W135: 3338280 | X135: 50 | Y135: 118391 | Z135: 1576485 | AA135: =W135-(Y135+Z135) -> 1643404 | AB135: 12424 | AC135: 0.678 | AD135: 0 | AE135: 0 | AF135: 12424 | AG135: 0.034 | AH135: 0.259 | AI135: 0.38 | AJ135: 2677648 | AK135: 50 | AL135: 113616 | AM135: 1247047 | AN135: =AJ135-(AL135+AM135) -> 1316985
... A172: RP_SS_N-400_I-4_R-0.99 | B172: 9158 | C172: 364.635 | D172: 9084 | E172: 0.022 | F172: 9158 | G172: 0.033 | H172: 0.614 | I172: 363.96 | J172: 357824652 | K172: 785136 | L172: 1005880 | M172: 177121160 | N172: =J172-(L172+M172) -> 179697612 | O172: 9158 | P172: 406.628 | Q172: 9084 | R172: 0.022 | S172: 0 | T172: 0.032 | U172: 0 | V172: 406.567 | W172: 394084209 | X172: 787462 | Y172: 1014649 | Z172: 195306569 | AA172: =W172-(Y172+Z172) -> 197762991 | AB172: 9158 | AC172: 363.589 | AD172: 0 | AE172: 0 | AF172: 9158 | AG172: 0.032 | AH172: 0.65 | AI172: 362.9 | AJ172: 357824652 | AK172: 785136 | AL172: 1005880 | AM172: 177121160 | AN172: =AJ172-(AL172+AM172) -> 179697612
A173: RP_SS_N-900_I-0_R-0.95 | B173: OOM | C173: 3600 | O173: OOM | P173: 3600 | AB173: OOM | AC173: 3600
A174: RP_SS_N-900_I-0_R-0.99 | B174: 22247 | C174: 3630.07 | D174: 22197 | E174: 0.118 | F174: 22247 | G174: 0.173 | H174: 3.759 | I174: 3626.01 | K174: 2705629 | L174: 1925607 | M174: 1112898013 | O174: 22207 | P174: 3620.73 | Q174: 22197 | R174: 0.118 | S174: 0 | T174: 0.173 | U174: 0 | V174: 3620.43 | X174: 2858655 | Y174: 1647471 | Z174: 1129847849 | AB174: 22247 | AC174: 3620.45 | AD174: 0 | AE174: 0 | AF174: 22247 | AG174: 0.174 | AH174: 4.016 | AI174: 3616.25 | AK174: 2705629 | AL174: 1925607 | AM174: 1112898013
A175: RP_SS_N-900_I-1_R-0.95 | B175: OOM | C175: 3600 | O175: OOM | P175: 3600 | AB175: OOM | AC175: 3600
A176: RP_SS_N-900_I-1_R-0.99 | B176: 21802 | C176: 3623.5 | D176: 21732 | E176: 0.146 | F176: 21802 | G176: 0.17 | H176: 3.479 | I176: 3619.7 | K176: 2610357 | L176: 2285761 | M176: 1138715792 | O176: 21763 | P176: 3615.95 | Q176: 21732 | R176: 0.146 | S176: 0 | T176: 0.17 | U176: 0 | V176: 3615.63 | X176: 2748855 | Y176: 1955974 | Z176: 1150877230 | AB176: 21802 | AC176: 3625.38 | AD176: 0 | AE176: 0 | AF176: 21802 | AG176: 0.17 | AH176: 4.219 | AI176: 3620.99 | AK176: 2607458 | AL176: 2280464 | AM176: 1133507768
A177: RP_SS_N-900_I-2_R-0.95 | B177: OOM | C177: 3600 | O177: OOM | P177: 3600 | AB177: OOM | AC177: 3600
A178: RP_SS_N-900_I-2_R-0.99 | B178: 22323 | C178: 3630.68 | D178: 22246 | E178: 0.129 | F178: 22323 | G178: 0.173 | H178: 3.608 | I178: 3626.77 | K178: 2685465 | L178: 2155170 | M178: 1132268230 | O178: 22278 | P178: 3617.5 | Q178: 22246 | R178: 0.129 | S178: 0 | T178: 0.173 | U178: 0 | V178: 3617.19 | X178: 2832567 | Y178: 1766537 | Z178: 1142283938 | AB178: 22323 | AC178: 3609.63 | AD178: 0 | AE178: 0 | AF178: 22323 | AG178: 0.173 | AH178: 4.009 | AI178: 3605.44 | AK178: 2681905 | AL178: 2149927 | AM178: 1126911336
A179: RP_SS_N-900_I-3_R-0.95 | B179: OOM | C179: 3600 | O179: OOM | P179: 3600 | AB179: OOM | AC179: 3600
A180: RP_SS_N-900_I-3_R-0.99 | B180: 21918 | C180: 3628.33 | D180: 21846 | E180: 0.101 | F180: 21918 | G180: 0.171 | H180: 3.546 | I180: 3624.51 | K180: 2678290 | L180: 2110393 | M180: 1114823276 | O180: 21876 | P180: 3610.84 | Q180: 21846 | R180: 0.101 | S180: 0 | T180: 0.171 | U180: 0 | V180: 3610.56 | X180: 2808268 | Y180: 1737157 | Z180: 1127317026 | AB180: 21918 | AC180: 3625.45 | AD180: 0 | AE180: 0 | AF180: 21918 | AG180: 0.17 | AH180: 3.957 | AI180: 3621.31 | AK180: 2678290 | AL180: 2110393 | AM180: 1114823276
A181: RP_SS_N-900_I-4_R-0.95 | B181: OOM | C181: 3600 | O181: OOM | P181: 3600 | AB181: OOM | AC181: 3600
A182: RP_SS_N-900_I-4_R-0.99 | B182: 22294 | C182: 3629.17 | D182: 22206 | E182: 0.146 | F182: 22294 | G182: 0.173 | H182: 3.63 | I182: 3625.22 | K182: 2677601 | L182: 2160683 | M182: 1126051043 | O182: 22235 | P182: 3612.09 | Q182: 22206 | R182: 0.146 | S182: 0 | T182: 0.173 | U182: 0 | V182: 3611.77 | X182: 2875788 | Y182: 1724050 | Z182: 1127531818 | AB182: 22294 | AC182: 3623.13 | AD182: 0 | AE182: 0 | AF182: 22294 | AG182: 0.173 | AH182: 4.009 | AI182: 3618.94 | AK182: 2669544 | AL182: 2122731 | AM182: 1115407202
B183: =AVERAGE(B3:B182) -> 12857.543 | C183: =AVERAGE(C3:C182) -> 232.17114 | D183: =AVERAGE(D3:D182) -> 12757.194 | E183: =AVERAGE(E3:E182) -> 0.029394286 | F183: =AVERAGE(F3:F182) -> 12851.966 | G183: =AVERAGE(G3:G182) -> 0.069485714 | H183: =AVERAGE(H3:H182) -> 0.6006 | I183: =AVERAGE(I3:I182) -> 135.24168 | ... AN183: =AVERAGE(AN3:AN182) -> 27329839
...

Sheet theta=3
A1: Filename | B1: 1-def | O1: 3-maskHLA | AB1: 4-maskTS
